Workbook

Sheet Setup
B2: MIDCAP-SMALLCAP EQUITY SCREENER | Nifty Midcap 50 + Nifty Smallcap 100 (Top 50 by Market Cap)
B4: ONE-TIME SETUP - EXCEL FOR MAC (Microsoft 365)
B5: 1. In Finder press Shift+Cmd+G and go to: ~/Library/Application Scripts/com.microsoft.Excel/
B6: (If 'Application Scripts' or 'com.microsoft.Excel' folders don't exist, create them with exactly those names.)
B7: 2. Copy 'YahooFetch.applescript' into that folder. This lets Excel call curl for web data - Mac VBA has no
B8: built-in HTTP, and curl also handles Yahoo's cookie handshake for fundamentals natively.
B9: 3. In Excel: Tools > Macro > Visual Basic Editor. Then File > Import File... and select 'ScreenerEngine.bas'.
B10: 4. Close the VBA editor. File > Save As > format 'Excel Macro-Enabled Workbook (.xlsm)'.
B11: 5. Tools > Macro > Macros... > select 'RefreshAllData' > Run. First refresh takes ~5-8 min (300 throttled calls).
B12: If macros were disabled on reopen: Excel menu > Preferences > Security > enable macros with notification.
B14: EVERY REFRESH AFTER THAT
B15: Tools > Macro > Macros... > RefreshAllData > Run (or Option+F8). Prices, fundamentals, Nifty trend and India
... B38: 2-3% per stock / 10% combined direct-equity ceiling. STCG 20% / LTCG 12.5% above Rs 1.25L applies on sales.

Sheet Dashboard
B2: MIDCAP-SMALLCAP SCREENER DASHBOARD
B4: Macro regime | C4: =Macro!B27 -> NEUTRAL | E4: TOP 12 BY COMPOSITE SCORE
B5: Regime score | C5: =Macro!B26 -> 53.5 | E5: Symbol | F5: Company | G5: Composite | H5: Verdict | I5: Conviction | J5: Key Risk
B6: Verdict counts | E6: =Recommendations!B2 -> YESBANK | F6: =Recommendations!C2 -> Yes Bank Ltd. | G6: =Recommendations!F2 -> 50.7 | H6: =Recommendations!G2 -> HOLD | I6: =Recommendations!H2 -> Low | J6: =Recommendations!J2 -> Rich valuation
B7: BUY | C7: =COUNTIF(Scoring!P2:P151,"BUY") -> 0 | E7: =Recommendations!B3 -> WAAREEENER | F7: =Recommendations!C3 -> Waaree Energies Ltd. | G7: =Recommendations!F3 -> 50.7 | H7: =Recommendations!G3 -> HOLD | I7: =Recommendations!H3 -> Low | J7: =Recommendations!J3 -> Rich valuation
B8: ACCUMULATE | C8: =COUNTIF(Scoring!P2:P151,"ACCUMULATE") -> 0 | E8: =Recommendations!B4 -> UPL | F8: =Recommendations!C4 -> UPL Ltd. | G8: =Recommendations!F4 -> 50.7 | H8: =Recommendations!G4 -> HOLD | I8: =Recommendations!H4 -> Low | J8: =Recommendations!J4 -> Rich valuation
B9: HOLD | C9: =COUNTIF(Scoring!P2:P151,"HOLD") -> 50 | E9: =Recommendations!B5 -> TIINDIA | F9: =Recommendations!C5 -> Tube Investments of India Ltd. | G9: =Recommendations!F5 -> 50.7 | H9: =Recommendations!G5 -> HOLD | I9: =Recommendations!H5 -> Low | J9: =Recommendations!J5 -> Rich valuation
B10: AVOID | C10: =COUNTIF(Scoring!P2:P151,"AVOID") -> 0 | E10: =Recommendations!B6 -> SWIGGY | F10: =Recommendations!C6 -> Swiggy Ltd. | G10: =Recommendations!F6 -> 50.7 | H10: =Recommendations!G6 -> HOLD | I10: =Recommendations!H6 -> Low | J10: =Recommendations!J6 -> Rich valuation
E11: =Recommendations!B7 -> SUZLON | F11: =Recommendations!C7 -> Suzlon Energy Ltd. | G11: =Recommendations!F7 -> 50.7 | H11: =Recommendations!G7 -> HOLD | I11: =Recommendations!H7 -> Low | J11: =Recommendations!J7 -> Rich valuation
B12: In-universe stocks | C12: =COUNTIF(Tickers!F2:F151,TRUE()) -> 50 | E12: =Recommendations!B8 -> SUPREMEIND | F12: =Recommendations!C8 -> Supreme Industries Ltd. | G12: =Recommendations!F8 -> 50.7 | H12: =Recommendations!G8 -> HOLD | I12: =Recommendations!H8 -> Low | J12: =Recommendations!J8 -> Rich valuation
E13: =Recommendations!B9 -> SRF | F13: =Recommendations!C9 -> SRF Ltd. | G13: =Recommendations!F9 -> 50.7 | H13: =Recommendations!G9 -> HOLD | I13: =Recommendations!H9 -> Low | J13: =Recommendations!J9 -> Rich valuation
B14: Workflow: Alt+F8 > RefreshAllData. Then review Recommendations sheet. Update Macro inputs monthly. | E14: =Recommendations!B10 -> SBICARD | F14: =Recommendations!C10 -> SBI Cards and Payment Services Ltd. | G14: =Recommendations!F10 -> 50.7 | H14: =Recommendations!G10 -> HOLD | I14: =Recommendations!H10 -> Low | J14: =Recommendations!J10 -> Rich valuation
E15: =Recommendations!B11 -> PRESTIGE | F15: =Recommendations!C11 -> Prestige Estates Projects Ltd. | G15: =Recommendations!F11 -> 50.7 | H15: =Recommendations!G11 -> HOLD | I15: =Recommendations!H11 -> Low | J15: =Recommendations!J11 -> Rich valuation
E16: =Recommendations!B12 -> POLYCAB | F16: =Recommendations!C12 -> Polycab India Ltd. | G16: =Recommendations!F12 -> 50.7 | H16: =Recommendations!G12 -> HOLD | I16: =Recommendations!H12 -> Low | J16: =Recommendations!J12 -> Rich valuation
E17: =Recommendations!B13 -> PHOENIXLTD | F17: =Recommendations!C13 -> Phoenix Mills Ltd. | G17: =Recommendations!F13 -> 50.7 | H17: =Recommendations!G13 -> HOLD | I17: =Recommendations!H13 -> Low | J17: =Recommendations!J13 -> Rich valuation

Sheet Control
A1: CONTROL PANEL - all blue cells are editable inputs
A3: Weight: Fundamentals | B3: 0.4 | C3: Must sum to 100% with the two below
A4: Weight: Technicals | B4: 0.4
A5: Weight: Macro regime | B5: 0.2
A7: BUY threshold (composite >=) | B7: 65 | C7: Composite is 0-100
A8: ACCUMULATE threshold (>=) | B8: 52
A9: HOLD threshold (>=) | B9: 40 | C9: Below this = AVOID
A11: Risk-Off smallcap penalty (pts) | B11: 8 | C11: Subtracted from smallcap composite when macro regime < 40
A12: Position size: BUY | B12: 0.025 | C12: Of total portfolio, per your 2-3% rule
A13: Position size: ACCUMULATE | B13: 0.0125 | C13: 10% combined direct-equity ceiling applies
A15: Weight check (must equal 100%) | B15: =B3+B4+B5 -> 1

Sheet Tickers
A1: Symbol | B1: Company Name | C1: Industry | D1: Index Bucket | E1: Yahoo Ticker | F1: In Universe
A2: APLAPOLLO | B2: APL Apollo Tubes Ltd. | C2: Capital Goods | D2: MIDCAP50 | E2: =A2&".NS" -> APLAPOLLO.NS | F2: =IF(D2="MIDCAP50",TRUE(),IF(ISNUMBER(Fundamentals!B2),SUMPRODUCT(($D$2:$D$151="SMALLCAP100")*ISNUMBER(Fundamentals!$B$2:$B$151)*(Fundamentals!$B$2:$B$151>Fundamentals!B2))+1<=50,FALSE())) -> TRUE
A3: AUBANK | B3: AU Small Finance Bank Ltd. | C3: Financial Services | D3: MIDCAP50 | E3: =A3&".NS" -> AUBANK.NS | F3: =IF(D3="MIDCAP50",TRUE(),IF(ISNUMBER(Fundamentals!B3),SUMPRODUCT(($D$2:$D$151="SMALLCAP100")*ISNUMBER(Fundamentals!$B$2:$B$151)*(Fundamentals!$B$2:$B$151>Fundamentals!B3))+1<=50,FALSE())) -> TRUE
A4: ALKEM | B4: Alkem Laboratories Ltd. | C4: Healthcare | D4: MIDCAP50 | E4: =A4&".NS" -> ALKEM.NS | F4: =IF(D4="MIDCAP50",TRUE(),IF(ISNUMBER(Fundamentals!B4),SUMPRODUCT(($D$2:$D$151="SMALLCAP100")*ISNUMBER(Fundamentals!$B$2:$B$151)*(Fundamentals!$B$2:$B$151>Fundamentals!B4))+1<=50,FALSE())) -> TRUE
A5: ASHOKLEY | B5: Ashok Leyland Ltd. | C5: Capital Goods | D5: MIDCAP50 | E5: =A5&".NS" -> ASHOKLEY.NS | F5: =IF(D5="MIDCAP50",TRUE(),IF(ISNUMBER(Fundamentals!B5),SUMPRODUCT(($D$2:$D$151="SMALLCAP100")*ISNUMBER(Fundamentals!$B$2:$B$151)*(Fundamentals!$B$2:$B$151>Fundamentals!B5))+1<=50,FALSE())) -> TRUE
A6: AUROPHARMA | B6: Aurobindo Pharma Ltd. | C6: Healthcare | D6: MIDCAP50 | E6: =A6&".NS" -> AUROPHARMA.NS | F6: =IF(D6="MIDCAP50",TRUE(),IF(ISNUMBER(Fundamentals!B6),SUMPRODUCT(($D$2:$D$151="SMALLCAP100")*ISNUMBER(Fundamentals!$B$2:$B$151)*(Fundamentals!$B$2:$B$151>Fundamentals!B6))+1<=50,FALSE())) -> TRUE
A7: BSE | B7: BSE Ltd. | C7: Financial Services | D7: MIDCAP50 | E7: =A7&".NS" -> BSE.NS | F7: =IF(D7="MIDCAP50",TRUE(),IF(ISNUMBER(Fundamentals!B7),SUMPRODUCT(($D$2:$D$151="SMALLCAP100")*ISNUMBER(Fundamentals!$B$2:$B$151)*(Fundamentals!$B$2:$B$151>Fundamentals!B7))+1<=50,FALSE())) -> TRUE
A8: BHARATFORG | B8: Bharat Forge Ltd. | C8: Automobile and Auto Components | D8: MIDCAP50 | E8: =A8&".NS" -> BHARATFORG.NS | F8: =IF(D8="MIDCAP50",TRUE(),IF(ISNUMBER(Fundamentals!B8),SUMPRODUCT(($D$2:$D$151="SMALLCAP100")*ISNUMBER(Fundamentals!$B$2:$B$151)*(Fundamentals!$B$2:$B$151>Fundamentals!B8))+1<=50,FALSE())) -> TRUE
A9: BHEL | B9: Bharat Heavy Electricals Ltd. | C9: Capital Goods | D9: MIDCAP50 | E9: =A9&".NS" -> BHEL.NS | F9: =IF(D9="MIDCAP50",TRUE(),IF(ISNUMBER(Fundamentals!B9),SUMPRODUCT(($D$2:$D$151="SMALLCAP100")*ISNUMBER(Fundamentals!$B$2:$B$151)*(Fundamentals!$B$2:$B$151>Fundamentals!B9))+1<=50,FALSE())) -> TRUE
A10: COFORGE | B10: Coforge Ltd. | C10: Information Technology | D10: MIDCAP50 | E10: =A10&".NS" -> COFORGE.NS | F10: =IF(D10="MIDCAP50",TRUE(),IF(ISNUMBER(Fundamentals!B10),SUMPRODUCT(($D$2:$D$151="SMALLCAP100")*ISNUMBER(Fundamentals!$B$2:$B$151)*(Fundamentals!$B$2:$B$151>Fundamentals!B10))+1<=50,FALSE())) -> TRUE
A11: COLPAL | B11: Colgate Palmolive (India) Ltd. | C11: Fast Moving Consumer Goods | D11: MIDCAP50 | E11: =A11&".NS" -> COLPAL.NS | F11: =IF(D11="MIDCAP50",TRUE(),IF(ISNUMBER(Fundamentals!B11),SUMPRODUCT(($D$2:$D$151="SMALLCAP100")*ISNUMBER(Fundamentals!$B$2:$B$151)*(Fundamentals!$B$2:$B$151>Fundamentals!B11))+1<=50,FALSE())) -> TRUE
A12: DABUR | B12: Dabur India Ltd. | C12: Fast Moving Consumer Goods | D12: MIDCAP50 | E12: =A12&".NS" -> DABUR.NS | F12: =IF(D12="MIDCAP50",TRUE(),IF(ISNUMBER(Fundamentals!B12),SUMPRODUCT(($D$2:$D$151="SMALLCAP100")*ISNUMBER(Fundamentals!$B$2:$B$151)*(Fundamentals!$B$2:$B$151>Fundamentals!B12))+1<=50,FALSE())) -> TRUE
A13: DIXON | B13: Dixon Technologies (India) Ltd. | C13: Consumer Durables | D13: MIDCAP50 | E13: =A13&".NS" -> DIXON.NS | F13: =IF(D13="MIDCAP50",TRUE(),IF(ISNUMBER(Fundamentals!B13),SUMPRODUCT(($D$2:$D$151="SMALLCAP100")*ISNUMBER(Fundamentals!$B$2:$B$151)*(Fundamentals!$B$2:$B$151>Fundamentals!B13))+1<=50,FALSE())) -> TRUE
... A151: ZENSARTECH | B151: Zensar Technolgies Ltd. | C151: Information Technology | D151: SMALLCAP100 | E151: =A151&".NS" -> ZENSARTECH.NS | F151: =IF(D151="MIDCAP50",TRUE(),IF(ISNUMBER(Fundamentals!B151),SUMPRODUCT(($D$2:$D$151="SMALLCAP100")*ISNUMBER(Fundamentals!$B$2:$B$151)*(Fundamentals!$B$2:$B$151>Fundamentals!B151))+1<=50,FALSE())) -> FALSE

Sheet PriceMetrics
A1: Symbol | B1: Last Price (Rs) | C1: 3Y CAGR | D1: 1Y Return | E1: 6M Return | F1: Ann. Volatility | G1: Max Drawdown 3Y | H1: RSI(14) | I1: SMA50 | J1: SMA200 | K1: % vs 200DMA | L1: MA Cross (1/-1) | M1: 52W High | N1: 52W Low | O1: % From 52W High | P1: Rel Strength 6M vs Nifty | Q1: Avg Volume 3M | R1: Status
A2: =Tickers!A2 -> APLAPOLLO
A3: =Tickers!A3 -> AUBANK
A4: =Tickers!A4 -> ALKEM
A5: =Tickers!A5 -> ASHOKLEY
A6: =Tickers!A6 -> AUROPHARMA
A7: =Tickers!A7 -> BSE
A8: =Tickers!A8 -> BHARATFORG
A9: =Tickers!A9 -> BHEL
A10: =Tickers!A10 -> COFORGE
A11: =Tickers!A11 -> COLPAL
A12: =Tickers!A12 -> DABUR
A13: =Tickers!A13 -> DIXON
... A151: =Tickers!A151 -> ZENSARTECH

Sheet Fundamentals
A1: Symbol | B1: Market Cap (Rs) | C1: Trailing P/E | D1: Forward P/E | E1: P/B | F1: ROE | G1: Debt/Equity (%) | H1: Revenue Growth YoY | I1: Earnings Growth YoY | J1: Net Margin | K1: Dividend Yield | L1: Beta | M1: Insider/Promoter Held | N1: Status
A2: =Tickers!A2 -> APLAPOLLO
A3: =Tickers!A3 -> AUBANK
A4: =Tickers!A4 -> ALKEM
A5: =Tickers!A5 -> ASHOKLEY
A6: =Tickers!A6 -> AUROPHARMA
A7: =Tickers!A7 -> BSE
A8: =Tickers!A8 -> BHARATFORG
A9: =Tickers!A9 -> BHEL
A10: =Tickers!A10 -> COFORGE
A11: =Tickers!A11 -> COLPAL
A12: =Tickers!A12 -> DABUR
A13: =Tickers!A13 -> DIXON
... A151: =Tickers!A151 -> ZENSARTECH

Sheet Macro
A1: MACRO REGIME - 20% of composite score
A3: AUTO-FETCHED (VBA writes on each refresh)
A4: Nifty 50 last close | D4: Source: Yahoo ^NSEI
A5: Nifty 50 200-DMA | D5: Source: Computed from 3Y series
A6: India VIX last close | D6: Source: Yahoo ^INDIAVIX
A8: AUTO SCORES (0-100, formulas)
A9: Trend score (Nifty vs 200-DMA) | B9: =IF(OR(NOT(ISNUMBER(B4)),NOT(ISNUMBER(B5)),B5=0),50,MIN(100,MAX(0,50+((B4-B5)/B5)*500))) -> 50 | D9: +/-1% vs 200DMA moves score +/-5pts; capped 0-100
A10: Volatility score (India VIX) | B10: =IF(NOT(ISNUMBER(B6)),50,IF(B6<13,85,IF(B6<17,65,IF(B6<22,40,15)))) -> 50 | D10: VIX <13 calm=85 | 13-17=65 | 17-22=40 | >22 stress=15
A12: MANUAL INPUTS - update monthly (blue cells, score each 0-100)
A13: RBI policy stance score | B13: 60 | D13: 100=deep cutting cycle, 50=neutral pause, 0=aggressive hiking. Source: rbi.org.in > Press Releases > Monetary Policy
A14: Inflation score (CPI) | B14: 60 | D14: CPI <4%=80+, 4-6% (in band)=50-70, >6% (above band)=<40. Source: mospi.gov.in > CPI press release
A15: FII flow score (3M net equity) | B15: 50 | D15: Strong inflows=80+, flat=50, heavy outflows=<30. Source: fpi.nsdl.co.in (FPI Monitor)
A16: Global cues score | B16: 50 | D16: US rates easing + soft-landing=70+, stable=50, risk-off (war/oil/US recession)=<35
A18: WEIGHTS (blue, must sum to 1)
A19: Wt: Trend | B19: 0.25
A20: Wt: VIX | B20: 0.15
A21: Wt: RBI | B21: 0.2
A22: Wt: CPI | B22: 0.15
A23: Wt: FII | B23: 0.15
A24: Wt: Global | B24: 0.1
A26: MACRO REGIME SCORE (0-100) | B26: =B19*B9+B20*B10+B21*B13+B22*B14+B23*B15+B24*B16 -> 53.5
A27: Regime label | B27: =IF(B26>=60,"RISK-ON",IF(B26>=40,"NEUTRAL","RISK-OFF")) -> NEUTRAL | D27: RISK-OFF auto-penalises smallcap composites by the Control!B11 amount

Sheet Scoring
A1: Symbol | B1: In Universe | C1: Score: Valuation | D1: Score: Quality | E1: Score: Growth | F1: Score: Leverage | G1: FUNDAMENTAL (40%) | H1: Score: Trend | I1: Score: Momentum | J1: Score: Risk-Adj | K1: TECHNICAL (40%) | L1: MACRO (20%) | M1: COMPOSITE | N1: CompAdj | O1: Eff. Composite | P1: VERDICT | Q1: Conviction | R1: Suggested Size | S1: Key Risk | T1: MinPillar | U1: RankVal
A2: =Tickers!A2 -> APLAPOLLO | B2: =Tickers!F2 -> TRUE | C2: =AVERAGE(IF(NOT(ISNUMBER(Fundamentals!C2)),50,IF(Fundamentals!C2<=0,15,100*(1-(SUMPRODUCT(($B$2:$B$151=TRUE())*ISNUMBER(Fundamentals!$C$2:$C$151)*(Fundamentals!$C$2:$C$151>0)*(Fundamentals!$C$2:$C$151<Fundamentals!C2))/MAX(1,SUMPRODUCT(($B$2:$B$151=TRUE())*ISNUMBER(Fundamentals!$C$2:$C$151)*(Fundamentals!$C$2:$C$151>0))))))),IF(NOT(ISNUMBER(Fundamentals!E2)),50,IF(Fundamentals!E2<=0,15,100*(1-(SUMPRODUCT(($B$2:$B$151=TRUE())*ISNUMBER(Fundamentals!$E$2:$E$151)*(Fundamentals!$E$2:$E$151>0)*(Fundamentals!$E$2:$E$151<Fundamentals!E2))/MAX(1,SUMPRODUCT(($B$2:$B$151=TRUE())*ISNUMBER(Fundamentals!$E$2:$E$151)*(Fundamentals!$E$2:$E$151>0)))))))) -> 50 | D2: =AVERAGE(IF(NOT(ISNUMBER(Fundamentals!F2)),50,100*(SUMPRODUCT(($B$2:$B$151=TRUE())*ISNUMBER(Fundamentals!$F$2:$F$151)*(Fundamentals!$F$2:$F$151<Fundamentals!F2))/MAX(1,SUMPRODUCT(($B$2:$B$151=TRUE())*ISNUMBER(Fundamentals!$F$2:$F$151))))),IF(NOT(ISNUMBER(Fundamentals!J2)),50,100*(SUMPRODUCT(($B$2:$B$151=TRUE())*ISNUMBER(Fundamentals!$J$2:$J$151)*(Fundamentals!$J$2:$J$151<Fundamentals!J2))/MAX(1,SUMPRODUCT(($B$2:$B$151=TRUE())*ISNUMBER(Fundamentals!$J$2:$J$151)))))) -> 50 | E2: =AVERAGE(IF(NOT(ISNUMBER(Fundamentals!H2)),50,100*(SUMPRODUCT(($B$2:$B$151=TRUE())*ISNUMBER(Fundamentals!$H$2:$H$151)*(Fundamentals!$H$2:$H$151<Fundamentals!H2))/MAX(1,SUMPRODUCT(($B$2:$B$151=TRUE())*ISNUMBER(Fundamentals!$H$2:$H$151))))),IF(NOT(ISNUMBER(Fundamentals!I2)),50,100*(SUMPRODUCT(($B$2:$B$151=TRUE())*ISNUMBER(Fundamentals!$I$2:$I$151)*(Fundamentals!$I$2:$I$151<Fundamentals!I2))/MAX(1,SUMPRODUCT(($B$2:$B$151=TRUE())*ISNUMBER(Fundamentals!$I$2:$I$151)))))) -> 50 | F2: =IF(Tickers!C2="Financial Services",50,IF(NOT(ISNUMBER(Fundamentals!G2)),50,100*(1-(SUMPRODUCT(($B$2:$B$151=TRUE())*ISNUMBER(Fundamentals!$G$2:$G$151)*(Fundamentals!$G$2:$G$151<Fundamentals!G2))/MAX(1,SUMPRODUCT(($B$2:$B$151=TRUE())*ISNUMBER(Fundamentals!$G$2:$G$151))))))) -> 50 | G2: =AVERAGE(C2:F2) -> 50 | H2: =MIN(100,MAX(0,IF(NOT(ISNUMBER(PriceMetrics!K2)),50,100*(SUMPRODUCT(($B$2:$B$151=TRUE())*ISNUMBER(PriceMetrics!$K$2:$K$151)*(PriceMetrics!$K$2:$K$151<PriceMetrics!K2))/MAX(1,SUMPRODUCT(($B$2:$B$151=TRUE())*ISNUMBER(PriceMetrics!$K$2:$K$151)))))+IF(ISNUMBER(PriceMetrics!L2),10*PriceMetrics!L2,0))) -> 50 | I2: =0.6*IF(NOT(ISNUMBER(PriceMetrics!P2)),50,100*(SUMPRODUCT(($B$2:$B$151=TRUE())*ISNUMBER(PriceMetrics!$P$2:$P$151)*(PriceMetrics!$P$2:$P$151<PriceMetrics!P2))/MAX(1,SUMPRODUCT(($B$2:$B$151=TRUE())*ISNUMBER(PriceMetrics!$P$2:$P$151)))))+0.4*IF(NOT(ISNUMBER(PriceMetrics!H2)),50,IF(PriceMetrics!H2>70,40,IF(PriceMetrics!H2>=50,100,IF(PriceMetrics!H2>=35,60,30)))) -> 50 | J2: =AVERAGE(IF(NOT(ISNUMBER(PriceMetrics!F2)),50,100*(1-(SUMPRODUCT(($B$2:$B$151=TRUE())*ISNUMBER(PriceMetrics!$F$2:$F$151)*(PriceMetrics!$F$2:$F$151<PriceMetrics!F2))/MAX(1,SUMPRODUCT(($B$2:$B$151=TRUE())*ISNUMBER(PriceMetrics!$F$2:$F$151)))))),IF(NOT(ISNUMBER(PriceMetrics!G2)),50,100*(1-(SUMPRODUCT(($B$2:$B$151=TRUE())*ISNUMBER(PriceMetrics!$G$2:$G$151)*(ABS(PriceMetrics!$G$2:$G$151)<ABS(PriceMetrics!G2)))/MAX(1,SUMPRODUCT(($B$2:$B$151=TRUE())*ISNUMBER(PriceMetrics!$G$2:$G$151))))))) -> 50 | K2: =AVERAGE(H2:J2) -> 50 | L2: =Macro!$B$26 -> 53.5 | M2: =Control!$B$3*100*G2/100+Control!$B$4*K2+Control!$B$5*L2 -> 50.7 | N2: =M2+ROW()/1000000 -> 50.700002 | O2: =M2-IF(AND(Tickers!D2="SMALLCAP100",Macro!$B$26<40),Control!$B$11,0) -> 50.7 | P2: =IF(B2=FALSE(),"-",IF(O2>=Control!$B$7,"BUY",IF(O2>=Control!$B$8,"ACCUMULATE",IF(O2>=Control!$B$9,"HOLD","AVOID")))) -> HOLD | Q2: =IF(B2=FALSE(),"",IF(OR(O2>=72,O2<=32),"High",IF(OR(O2>=62,O2<=42),"Medium","Low"))) -> Low | R2: =IF(P2="BUY",Control!$B$12,IF(P2="ACCUMULATE",Control!$B$13,0)) -> 0 | S2: =IF(B2=FALSE(),"",IF(T2=C2,"Rich valuation",IF(T2=E2,"Weak growth",IF(T2=F2,"Balance-sheet leverage",IF(T2=I2,"Negative momentum","High volatility/drawdown"))))) -> Rich valuation | T2: =MIN(C2,E2,F2,I2,J2) -> 50 | U2: =IF(B2=TRUE(),N2,-1000+ROW()/1000000) -> 50.700002
A3: =Tickers!A3 -> AUBANK | B3: =Tickers!F3 -> TRUE | C3: =AVERAGE(IF(NOT(ISNUMBER(Fundamentals!C3)),50,IF(Fundamentals!C3<=0,15,100*(1-(SUMPRODUCT(($B$2:$B$151=TRUE())*ISNUMBER(Fundamentals!$C$2:$C$151)*(Fundamentals!$C$2:$C$151>0)*(Fundamentals!$C$2:$C$151<Fundamentals!C3))/MAX(1,SUMPRODUCT(($B$2:$B$151=TRUE())*ISNUMBER(Fundamentals!$C$2:$C$151)*(Fundamentals!$C$2:$C$151>0))))))),IF(NOT(ISNUMBER(Fundamentals!E3)),50,IF(Fundamentals!E3<=0,15,100*(1-(SUMPRODUCT(($B$2:$B$151=TRUE())*ISNUMBER(Fundamentals!$E$2:$E$151)*(Fundamentals!$E$2:$E$151>0)*(Fundamentals!$E$2:$E$151<Fundamentals!E3))/MAX(1,SUMPRODUCT(($B$2:$B$151=TRUE())*ISNUMBER(Fundamentals!$E$2:$E$151)*(Fundamentals!$E$2:$E$151>0)))))))) -> 50 | D3: =AVERAGE(IF(NOT(ISNUMBER(Fundamentals!F3)),50,100*(SUMPRODUCT(($B$2:$B$151=TRUE())*ISNUMBER(Fundamentals!$F$2:$F$151)*(Fundamentals!$F$2:$F$151<Fundamentals!F3))/MAX(1,SUMPRODUCT(($B$2:$B$151=TRUE())*ISNUMBER(Fundamentals!$F$2:$F$151))))),IF(NOT(ISNUMBER(Fundamentals!J3)),50,100*(SUMPRODUCT(($B$2:$B$151=TRUE())*ISNUMBER(Fundamentals!$J$2:$J$151)*(Fundamentals!$J$2:$J$151<Fundamentals!J3))/MAX(1,SUMPRODUCT(($B$2:$B$151=TRUE())*ISNUMBER(Fundamentals!$J$2:$J$151)))))) -> 50 | E3: =AVERAGE(IF(NOT(ISNUMBER(Fundamentals!H3)),50,100*(SUMPRODUCT(($B$2:$B$151=TRUE())*ISNUMBER(Fundamentals!$H$2:$H$151)*(Fundamentals!$H$2:$H$151<Fundamentals!H3))/MAX(1,SUMPRODUCT(($B$2:$B$151=TRUE())*ISNUMBER(Fundamentals!$H$2:$H$151))))),IF(NOT(ISNUMBER(Fundamentals!I3)),50,100*(SUMPRODUCT(($B$2:$B$151=TRUE())*ISNUMBER(Fundamentals!$I$2:$I$151)*(Fundamentals!$I$2:$I$151<Fundamentals!I3))/MAX(1,SUMPRODUCT(($B$2:$B$151=TRUE())*ISNUMBER(Fundamentals!$I$2:$I$151)))))) -> 50 | F3: =IF(Tickers!C3="Financial Services",50,IF(NOT(ISNUMBER(Fundamentals!G3)),50,100*(1-(SUMPRODUCT(($B$2:$B$151=TRUE())*ISNUMBER(Fundamentals!$G$2:$G$151)*(Fundamentals!$G$2:$G$151<Fundamentals!G3))/MAX(1,SUMPRODUCT(($B$2:$B$151=TRUE())*ISNUMBER(Fundamentals!$G$2:$G$151))))))) -> 50 | G3: =AVERAGE(C3:F3) -> 50 | H3: =MIN(100,MAX(0,IF(NOT(ISNUMBER(PriceMetrics!K3)),50,100*(SUMPRODUCT(($B$2:$B$151=TRUE())*ISNUMBER(PriceMetrics!$K$2:$K$151)*(PriceMetrics!$K$2:$K$151<PriceMetrics!K3))/MAX(1,SUMPRODUCT(($B$2:$B$151=TRUE())*ISNUMBER(PriceMetrics!$K$2:$K$151)))))+IF(ISNUMBER(PriceMetrics!L3),10*PriceMetrics!L3,0))) -> 50 | I3: =0.6*IF(NOT(ISNUMBER(PriceMetrics!P3)),50,100*(SUMPRODUCT(($B$2:$B$151=TRUE())*ISNUMBER(PriceMetrics!$P$2:$P$151)*(PriceMetrics!$P$2:$P$151<PriceMetrics!P3))/MAX(1,SUMPRODUCT(($B$2:$B$151=TRUE())*ISNUMBER(PriceMetrics!$P$2:$P$151)))))+0.4*IF(NOT(ISNUMBER(PriceMetrics!H3)),50,IF(PriceMetrics!H3>70,40,IF(PriceMetrics!H3>=50,100,IF(PriceMetrics!H3>=35,60,30)))) -> 50 | J3: =AVERAGE(IF(NOT(ISNUMBER(PriceMetrics!F3)),50,100*(1-(SUMPRODUCT(($B$2:$B$151=TRUE())*ISNUMBER(PriceMetrics!$F$2:$F$151)*(PriceMetrics!$F$2:$F$151<PriceMetrics!F3))/MAX(1,SUMPRODUCT(($B$2:$B$151=TRUE())*ISNUMBER(PriceMetrics!$F$2:$F$151)))))),IF(NOT(ISNUMBER(PriceMetrics!G3)),50,100*(1-(SUMPRODUCT(($B$2:$B$151=TRUE())*ISNUMBER(PriceMetrics!$G$2:$G$151)*(ABS(PriceMetrics!$G$2:$G$151)<ABS(PriceMetrics!G3)))/MAX(1,SUMPRODUCT(($B$2:$B$151=TRUE())*ISNUMBER(PriceMetrics!$G$2:$G$151))))))) -> 50 | K3: =AVERAGE(H3:J3) -> 50 | L3: =Macro!$B$26 -> 53.5 | M3: =Control!$B$3*100*G3/100+Control!$B$4*K3+Control!$B$5*L3 -> 50.7 | N3: =M3+ROW()/1000000 -> 50.700003 | O3: =M3-IF(AND(Tickers!D3="SMALLCAP100",Macro!$B$26<40),Control!$B$11,0) -> 50.7 | P3: =IF(B3=FALSE(),"-",IF(O3>=Control!$B$7,"BUY",IF(O3>=Control!$B$8,"ACCUMULATE",IF(O3>=Control!$B$9,"HOLD","AVOID")))) -> HOLD | Q3: =IF(B3=FALSE(),"",IF(OR(O3>=72,O3<=32),"High",IF(OR(O3>=62,O3<=42),"Medium","Low"))) -> Low | R3: =IF(P3="BUY",Control!$B$12,IF(P3="ACCUMULATE",Control!$B$13,0)) -> 0 | S3: =IF(B3=FALSE(),"",IF(T3=C3,"Rich valuation",IF(T3=E3,"Weak growth",IF(T3=F3,"Balance-sheet leverage",IF(T3=I3,"Negative momentum","High volatility/drawdown"))))) -> Rich valuation | T3: =MIN(C3,E3,F3,I3,J3) -> 50 | U3: =IF(B3=TRUE(),N3,-1000+ROW()/1000000) -> 50.700003
A4: =Tickers!A4 -> ALKEM | B4: =Tickers!F4 -> TRUE | C4: =AVERAGE(IF(NOT(ISNUMBER(Fundamentals!C4)),50,IF(Fundamentals!C4<=0,15,100*(1-(SUMPRODUCT(($B$2:$B$151=TRUE())*ISNUMBER(Fundamentals!$C$2:$C$151)*(Fundamentals!$C$2:$C$151>0)*(Fundamentals!$C$2:$C$151<Fundamentals!C4))/MAX(1,SUMPRODUCT(($B$2:$B$151=TRUE())*ISNUMBER(Fundamentals!$C$2:$C$151)*(Fundamentals!$C$2:$C$151>0))))))),IF(NOT(ISNUMBER(Fundamentals!E4)),50,IF(Fundamentals!E4<=0,15,100*(1-(SUMPRODUCT(($B$2:$B$151=TRUE())*ISNUMBER(Fundamentals!$E$2:$E$151)*(Fundamentals!$E$2:$E$151>0)*(Fundamentals!$E$2:$E$151<Fundamentals!E4))/MAX(1,SUMPRODUCT(($B$2:$B$151=TRUE())*ISNUMBER(Fundamentals!$E$2:$E$151)*(Fundamentals!$E$2:$E$151>0)))))))) -> 50 | D4: =AVERAGE(IF(NOT(ISNUMBER(Fundamentals!F4)),50,100*(SUMPRODUCT(($B$2:$B$151=TRUE())*ISNUMBER(Fundamentals!$F$2:$F$151)*(Fundamentals!$F$2:$F$151<Fundamentals!F4))/MAX(1,SUMPRODUCT(($B$2:$B$151=TRUE())*ISNUMBER(Fundamentals!$F$2:$F$151))))),IF(NOT(ISNUMBER(Fundamentals!J4)),50,100*(SUMPRODUCT(($B$2:$B$151=TRUE())*ISNUMBER(Fundamentals!$J$2:$J$151)*(Fundamentals!$J$2:$J$151<Fundamentals!J4))/MAX(1,SUMPRODUCT(($B$2:$B$151=TRUE())*ISNUMBER(Fundamentals!$J$2:$J$151)))))) -> 50 | E4: =AVERAGE(IF(NOT(ISNUMBER(Fundamentals!H4)),50,100*(SUMPRODUCT(($B$2:$B$151=TRUE())*ISNUMBER(Fundamentals!$H$2:$H$151)*(Fundamentals!$H$2:$H$151<Fundamentals!H4))/MAX(1,SUMPRODUCT(($B$2:$B$151=TRUE())*ISNUMBER(Fundamentals!$H$2:$H$151))))),IF(NOT(ISNUMBER(Fundamentals!I4)),50,100*(SUMPRODUCT(($B$2:$B$151=TRUE())*ISNUMBER(Fundamentals!$I$2:$I$151)*(Fundamentals!$I$2:$I$151<Fundamentals!I4))/MAX(1,SUMPRODUCT(($B$2:$B$151=TRUE())*ISNUMBER(Fundamentals!$I$2:$I$151)))))) -> 50 | F4: =IF(Tickers!C4="Financial Services",50,IF(NOT(ISNUMBER(Fundamentals!G4)),50,100*(1-(SUMPRODUCT(($B$2:$B$151=TRUE())*ISNUMBER(Fundamentals!$G$2:$G$151)*(Fundamentals!$G$2:$G$151<Fundamentals!G4))/MAX(1,SUMPRODUCT(($B$2:$B$151=TRUE())*ISNUMBER(Fundamentals!$G$2:$G$151))))))) -> 50 | G4: =AVERAGE(C4:F4) -> 50 | H4: =MIN(100,MAX(0,IF(NOT(ISNUMBER(PriceMetrics!K4)),50,100*(SUMPRODUCT(($B$2:$B$151=TRUE())*ISNUMBER(PriceMetrics!$K$2:$K$151)*(PriceMetrics!$K$2:$K$151<PriceMetrics!K4))/MAX(1,SUMPRODUCT(($B$2:$B$151=TRUE())*ISNUMBER(PriceMetrics!$K$2:$K$151)))))+IF(ISNUMBER(PriceMetrics!L4),10*PriceMetrics!L4,0))) -> 50 | I4: =0.6*IF(NOT(ISNUMBER(PriceMetrics!P4)),50,100*(SUMPRODUCT(($B$2:$B$151=TRUE())*ISNUMBER(PriceMetrics!$P$2:$P$151)*(PriceMetrics!$P$2:$P$151<PriceMetrics!P4))/MAX(1,SUMPRODUCT(($B$2:$B$151=TRUE())*ISNUMBER(PriceMetrics!$P$2:$P$151)))))+0.4*IF(NOT(ISNUMBER(PriceMetrics!H4)),50,IF(PriceMetrics!H4>70,40,IF(PriceMetrics!H4>=50,100,IF(PriceMetrics!H4>=35,60,30)))) -> 50 | J4: =AVERAGE(IF(NOT(ISNUMBER(PriceMetrics!F4)),50,100*(1-(SUMPRODUCT(($B$2:$B$151=TRUE())*ISNUMBER(PriceMetrics!$F$2:$F$151)*(PriceMetrics!$F$2:$F$151<PriceMetrics!F4))/MAX(1,SUMPRODUCT(($B$2:$B$151=TRUE())*ISNUMBER(PriceMetrics!$F$2:$F$151)))))),IF(NOT(ISNUMBER(PriceMetrics!G4)),50,100*(1-(SUMPRODUCT(($B$2:$B$151=TRUE())*ISNUMBER(PriceMetrics!$G$2:$G$151)*(ABS(PriceMetrics!$G$2:$G$151)<ABS(PriceMetrics!G4)))/MAX(1,SUMPRODUCT(($B$2:$B$151=TRUE())*ISNUMBER(PriceMetrics!$G$2:$G$151))))))) -> 50 | K4: =AVERAGE(H4:J4) -> 50 | L4: =Macro!$B$26 -> 53.5 | M4: =Control!$B$3*100*G4/100+Control!$B$4*K4+Control!$B$5*L4 -> 50.7 | N4: =M4+ROW()/1000000 -> 50.700004 | O4: =M4-IF(AND(Tickers!D4="SMALLCAP100",Macro!$B$26<40),Control!$B$11,0) -> 50.7 | P4: =IF(B4=FALSE(),"-",IF(O4>=Control!$B$7,"BUY",IF(O4>=Control!$B$8,"ACCUMULATE",IF(O4>=Control!$B$9,"HOLD","AVOID")))) -> HOLD | Q4: =IF(B4=FALSE(),"",IF(OR(O4>=72,O4<=32),"High",IF(OR(O4>=62,O4<=42),"Medium","Low"))) -> Low | R4: =IF(P4="BUY",Control!$B$12,IF(P4="ACCUMULATE",Control!$B$13,0)) -> 0 | S4: =IF(B4=FALSE(),"",IF(T4=C4,"Rich valuation",IF(T4=E4,"Weak growth",IF(T4=F4,"Balance-sheet leverage",IF(T4=I4,"Negative momentum","High volatility/drawdown"))))) -> Rich valuation | T4: =MIN(C4,E4,F4,I4,J4) -> 50 | U4: =IF(B4=TRUE(),N4,-1000+ROW()/1000000) -> 50.700004
A5: =Tickers!A5 -> ASHOKLEY | B5: =Tickers!F5 -> TRUE | C5: =AVERAGE(IF(NOT(ISNUMBER(Fundamentals!C5)),50,IF(Fundamentals!C5<=0,15,100*(1-(SUMPRODUCT(($B$2:$B$151=TRUE())*ISNUMBER(Fundamentals!$C$2:$C$151)*(Fundamentals!$C$2:$C$151>0)*(Fundamentals!$C$2:$C$151<Fundamentals!C5))/MAX(1,SUMPRODUCT(($B$2:$B$151=TRUE())*ISNUMBER(Fundamentals!$C$2:$C$151)*(Fundamentals!$C$2:$C$151>0))))))),IF(NOT(ISNUMBER(Fundamentals!E5)),50,IF(Fundamentals!E5<=0,15,100*(1-(SUMPRODUCT(($B$2:$B$151=TRUE())*ISNUMBER(Fundamentals!$E$2:$E$151)*(Fundamentals!$E$2:$E$151>0)*(Fundamentals!$E$2:$E$151<Fundamentals!E5))/MAX(1,SUMPRODUCT(($B$2:$B$151=TRUE())*ISNUMBER(Fundamentals!$E$2:$E$151)*(Fundamentals!$E$2:$E$151>0)))))))) -> 50 | D5: =AVERAGE(IF(NOT(ISNUMBER(Fundamentals!F5)),50,100*(SUMPRODUCT(($B$2:$B$151=TRUE())*ISNUMBER(Fundamentals!$F$2:$F$151)*(Fundamentals!$F$2:$F$151<Fundamentals!F5))/MAX(1,SUMPRODUCT(($B$2:$B$151=TRUE())*ISNUMBER(Fundamentals!$F$2:$F$151))))),IF(NOT(ISNUMBER(Fundamentals!J5)),50,100*(SUMPRODUCT(($B$2:$B$151=TRUE())*ISNUMBER(Fundamentals!$J$2:$J$151)*(Fundamentals!$J$2:$J$151<Fundamentals!J5))/MAX(1,SUMPRODUCT(($B$2:$B$151=TRUE())*ISNUMBER(Fundamentals!$J$2:$J$151)))))) -> 50 | E5: =AVERAGE(IF(NOT(ISNUMBER(Fundamentals!H5)),50,100*(SUMPRODUCT(($B$2:$B$151=TRUE())*ISNUMBER(Fundamentals!$H$2:$H$151)*(Fundamentals!$H$2:$H$151<Fundamentals!H5))/MAX(1,SUMPRODUCT(($B$2:$B$151=TRUE())*ISNUMBER(Fundamentals!$H$2:$H$151))))),IF(NOT(ISNUMBER(Fundamentals!I5)),50,100*(SUMPRODUCT(($B$2:$B$151=TRUE())*ISNUMBER(Fundamentals!$I$2:$I$151)*(Fundamentals!$I$2:$I$151<Fundamentals!I5))/MAX(1,SUMPRODUCT(($B$2:$B$151=TRUE())*ISNUMBER(Fundamentals!$I$2:$I$151)))))) -> 50 | F5: =IF(Tickers!C5="Financial Services",50,IF(NOT(ISNUMBER(Fundamentals!G5)),50,100*(1-(SUMPRODUCT(($B$2:$B$151=TRUE())*ISNUMBER(Fundamentals!$G$2:$G$151)*(Fundamentals!$G$2:$G$151<Fundamentals!G5))/MAX(1,SUMPRODUCT(($B$2:$B$151=TRUE())*ISNUMBER(Fundamentals!$G$2:$G$151))))))) -> 50 | G5: =AVERAGE(C5:F5) -> 50 | H5: =MIN(100,MAX(0,IF(NOT(ISNUMBER(PriceMetrics!K5)),50,100*(SUMPRODUCT(($B$2:$B$151=TRUE())*ISNUMBER(PriceMetrics!$K$2:$K$151)*(PriceMetrics!$K$2:$K$151<PriceMetrics!K5))/MAX(1,SUMPRODUCT(($B$2:$B$151=TRUE())*ISNUMBER(PriceMetrics!$K$2:$K$151)))))+IF(ISNUMBER(PriceMetrics!L5),10*PriceMetrics!L5,0))) -> 50 | I5: =0.6*IF(NOT(ISNUMBER(PriceMetrics!P5)),50,100*(SUMPRODUCT(($B$2:$B$151=TRUE())*ISNUMBER(PriceMetrics!$P$2:$P$151)*(PriceMetrics!$P$2:$P$151<PriceMetrics!P5))/MAX(1,SUMPRODUCT(($B$2:$B$151=TRUE())*ISNUMBER(PriceMetrics!$P$2:$P$151)))))+0.4*IF(NOT(ISNUMBER(PriceMetrics!H5)),50,IF(PriceMetrics!H5>70,40,IF(PriceMetrics!H5>=50,100,IF(PriceMetrics!H5>=35,60,30)))) -> 50 | J5: =AVERAGE(IF(NOT(ISNUMBER(PriceMetrics!F5)),50,100*(1-(SUMPRODUCT(($B$2:$B$151=TRUE())*ISNUMBER(PriceMetrics!$F$2:$F$151)*(PriceMetrics!$F$2:$F$151<PriceMetrics!F5))/MAX(1,SUMPRODUCT(($B$2:$B$151=TRUE())*ISNUMBER(PriceMetrics!$F$2:$F$151)))))),IF(NOT(ISNUMBER(PriceMetrics!G5)),50,100*(1-(SUMPRODUCT(($B$2:$B$151=TRUE())*ISNUMBER(PriceMetrics!$G$2:$G$151)*(ABS(PriceMetrics!$G$2:$G$151)<ABS(PriceMetrics!G5)))/MAX(1,SUMPRODUCT(($B$2:$B$151=TRUE())*ISNUMBER(PriceMetrics!$G$2:$G$151))))))) -> 50 | K5: =AVERAGE(H5:J5) -> 50 | L5: =Macro!$B$26 -> 53.5 | M5: =Control!$B$3*100*G5/100+Control!$B$4*K5+Control!$B$5*L5 -> 50.7 | N5: =M5+ROW()/1000000 -> 50.700005 | O5: =M5-IF(AND(Tickers!D5="SMALLCAP100",Macro!$B$26<40),Control!$B$11,0) -> 50.7 | P5: =IF(B5=FALSE(),"-",IF(O5>=Control!$B$7,"BUY",IF(O5>=Control!$B$8,"ACCUMULATE",IF(O5>=Control!$B$9,"HOLD","AVOID")))) -> HOLD | Q5: =IF(B5=FALSE(),"",IF(OR(O5>=72,O5<=32),"High",IF(OR(O5>=62,O5<=42),"Medium","Low"))) -> Low | R5: =IF(P5="BUY",Control!$B$12,IF(P5="ACCUMULATE",Control!$B$13,0)) -> 0 | S5: =IF(B5=FALSE(),"",IF(T5=C5,"Rich valuation",IF(T5=E5,"Weak growth",IF(T5=F5,"Balance-sheet leverage",IF(T5=I5,"Negative momentum","High volatility/drawdown"))))) -> Rich valuation | T5: =MIN(C5,E5,F5,I5,J5) -> 50 | U5: =IF(B5=TRUE(),N5,-1000+ROW()/1000000) -> 50.700005
A6: =Tickers!A6 -> AUROPHARMA | B6: =Tickers!F6 -> TRUE | C6: =AVERAGE(IF(NOT(ISNUMBER(Fundamentals!C6)),50,IF(Fundamentals!C6<=0,15,100*(1-(SUMPRODUCT(($B$2:$B$151=TRUE())*ISNUMBER(Fundamentals!$C$2:$C$151)*(Fundamentals!$C$2:$C$151>0)*(Fundamentals!$C$2:$C$151<Fundamentals!C6))/MAX(1,SUMPRODUCT(($B$2:$B$151=TRUE())*ISNUMBER(Fundamentals!$C$2:$C$151)*(Fundamentals!$C$2:$C$151>0))))))),IF(NOT(ISNUMBER(Fundamentals!E6)),50,IF(Fundamentals!E6<=0,15,100*(1-(SUMPRODUCT(($B$2:$B$151=TRUE())*ISNUMBER(Fundamentals!$E$2:$E$151)*(Fundamentals!$E$2:$E$151>0)*(Fundamentals!$E$2:$E$151<Fundamentals!E6))/MAX(1,SUMPRODUCT(($B$2:$B$151=TRUE())*ISNUMBER(Fundamentals!$E$2:$E$151)*(Fundamentals!$E$2:$E$151>0)))))))) -> 50 | D6: =AVERAGE(IF(NOT(ISNUMBER(Fundamentals!F6)),50,100*(SUMPRODUCT(($B$2:$B$151=TRUE())*ISNUMBER(Fundamentals!$F$2:$F$151)*(Fundamentals!$F$2:$F$151<Fundamentals!F6))/MAX(1,SUMPRODUCT(($B$2:$B$151=TRUE())*ISNUMBER(Fundamentals!$F$2:$F$151))))),IF(NOT(ISNUMBER(Fundamentals!J6)),50,100*(SUMPRODUCT(($B$2:$B$151=TRUE())*ISNUMBER(Fundamentals!$J$2:$J$151)*(Fundamentals!$J$2:$J$151<Fundamentals!J6))/MAX(1,SUMPRODUCT(($B$2:$B$151=TRUE())*ISNUMBER(Fundamentals!$J$2:$J$151)))))) -> 50 | E6: =AVERAGE(IF(NOT(ISNUMBER(Fundamentals!H6)),50,100*(SUMPRODUCT(($B$2:$B$151=TRUE())*ISNUMBER(Fundamentals!$H$2:$H$151)*(Fundamentals!$H$2:$H$151<Fundamentals!H6))/MAX(1,SUMPRODUCT(($B$2:$B$151=TRUE())*ISNUMBER(Fundamentals!$H$2:$H$151))))),IF(NOT(ISNUMBER(Fundamentals!I6)),50,100*(SUMPRODUCT(($B$2:$B$151=TRUE())*ISNUMBER(Fundamentals!$I$2:$I$151)*(Fundamentals!$I$2:$I$151<Fundamentals!I6))/MAX(1,SUMPRODUCT(($B$2:$B$151=TRUE())*ISNUMBER(Fundamentals!$I$2:$I$151)))))) -> 50 | F6: =IF(Tickers!C6="Financial Services",50,IF(NOT(ISNUMBER(Fundamentals!G6)),50,100*(1-(SUMPRODUCT(($B$2:$B$151=TRUE())*ISNUMBER(Fundamentals!$G$2:$G$151)*(Fundamentals!$G$2:$G$151<Fundamentals!G6))/MAX(1,SUMPRODUCT(($B$2:$B$151=TRUE())*ISNUMBER(Fundamentals!$G$2:$G$151))))))) -> 50 | G6: =AVERAGE(C6:F6) -> 50 | H6: =MIN(100,MAX(0,IF(NOT(ISNUMBER(PriceMetrics!K6)),50,100*(SUMPRODUCT(($B$2:$B$151=TRUE())*ISNUMBER(PriceMetrics!$K$2:$K$151)*(PriceMetrics!$K$2:$K$151<PriceMetrics!K6))/MAX(1,SUMPRODUCT(($B$2:$B$151=TRUE())*ISNUMBER(PriceMetrics!$K$2:$K$151)))))+IF(ISNUMBER(PriceMetrics!L6),10*PriceMetrics!L6,0))) -> 50 | I6: =0.6*IF(NOT(ISNUMBER(PriceMetrics!P6)),50,100*(SUMPRODUCT(($B$2:$B$151=TRUE())*ISNUMBER(PriceMetrics!$P$2:$P$151)*(PriceMetrics!$P$2:$P$151<PriceMetrics!P6))/MAX(1,SUMPRODUCT(($B$2:$B$151=TRUE())*ISNUMBER(PriceMetrics!$P$2:$P$151)))))+0.4*IF(NOT(ISNUMBER(PriceMetrics!H6)),50,IF(PriceMetrics!H6>70,40,IF(PriceMetrics!H6>=50,100,IF(PriceMetrics!H6>=35,60,30)))) -> 50 | J6: =AVERAGE(IF(NOT(ISNUMBER(PriceMetrics!F6)),50,100*(1-(SUMPRODUCT(($B$2:$B$151=TRUE())*ISNUMBER(PriceMetrics!$F$2:$F$151)*(PriceMetrics!$F$2:$F$151<PriceMetrics!F6))/MAX(1,SUMPRODUCT(($B$2:$B$151=TRUE())*ISNUMBER(PriceMetrics!$F$2:$F$151)))))),IF(NOT(ISNUMBER(PriceMetrics!G6)),50,100*(1-(SUMPRODUCT(($B$2:$B$151=TRUE())*ISNUMBER(PriceMetrics!$G$2:$G$151)*(ABS(PriceMetrics!$G$2:$G$151)<ABS(PriceMetrics!G6)))/MAX(1,SUMPRODUCT(($B$2:$B$151=TRUE())*ISNUMBER(PriceMetrics!$G$2:$G$151))))))) -> 50 | K6: =AVERAGE(H6:J6) -> 50 | L6: =Macro!$B$26 -> 53.5 | M6: =Control!$B$3*100*G6/100+Control!$B$4*K6+Control!$B$5*L6 -> 50.7 | N6: =M6+ROW()/1000000 -> 50.700006 | O6: =M6-IF(AND(Tickers!D6="SMALLCAP100",Macro!$B$26<40),Control!$B$11,0) -> 50.7 | P6: =IF(B6=FALSE(),"-",IF(O6>=Control!$B$7,"BUY",IF(O6>=Control!$B$8,"ACCUMULATE",IF(O6>=Control!$B$9,"HOLD","AVOID")))) -> HOLD | Q6: =IF(B6=FALSE(),"",IF(OR(O6>=72,O6<=32),"High",IF(OR(O6>=62,O6<=42),"Medium","Low"))) -> Low | R6: =IF(P6="BUY",Control!$B$12,IF(P6="ACCUMULATE",Control!$B$13,0)) -> 0 | S6: =IF(B6=FALSE(),"",IF(T6=C6,"Rich valuation",IF(T6=E6,"Weak growth",IF(T6=F6,"Balance-sheet leverage",IF(T6=I6,"Negative momentum","High volatility/drawdown"))))) -> Rich valuation | T6: =MIN(C6,E6,F6,I6,J6) -> 50 | U6: =IF(B6=TRUE(),N6,-1000+ROW()/1000000) -> 50.700006
A7: =Tickers!A7 -> BSE | B7: =Tickers!F7 -> TRUE | C7: =AVERAGE(IF(NOT(ISNUMBER(Fundamentals!C7)),50,IF(Fundamentals!C7<=0,15,100*(1-(SUMPRODUCT(($B$2:$B$151=TRUE())*ISNUMBER(Fundamentals!$C$2:$C$151)*(Fundamentals!$C$2:$C$151>0)*(Fundamentals!$C$2:$C$151<Fundamentals!C7))/MAX(1,SUMPRODUCT(($B$2:$B$151=TRUE())*ISNUMBER(Fundamentals!$C$2:$C$151)*(Fundamentals!$C$2:$C$151>0))))))),IF(NOT(ISNUMBER(Fundamentals!E7)),50,IF(Fundamentals!E7<=0,15,100*(1-(SUMPRODUCT(($B$2:$B$151=TRUE())*ISNUMBER(Fundamentals!$E$2:$E$151)*(Fundamentals!$E$2:$E$151>0)*(Fundamentals!$E$2:$E$151<Fundamentals!E7))/MAX(1,SUMPRODUCT(($B$2:$B$151=TRUE())*ISNUMBER(Fundamentals!$E$2:$E$151)*(Fundamentals!$E$2:$E$151>0)))))))) -> 50 | D7: =AVERAGE(IF(NOT(ISNUMBER(Fundamentals!F7)),50,100*(SUMPRODUCT(($B$2:$B$151=TRUE())*ISNUMBER(Fundamentals!$F$2:$F$151)*(Fundamentals!$F$2:$F$151<Fundamentals!F7))/MAX(1,SUMPRODUCT(($B$2:$B$151=TRUE())*ISNUMBER(Fundamentals!$F$2:$F$151))))),IF(NOT(ISNUMBER(Fundamentals!J7)),50,100*(SUMPRODUCT(($B$2:$B$151=TRUE())*ISNUMBER(Fundamentals!$J$2:$J$151)*(Fundamentals!$J$2:$J$151<Fundamentals!J7))/MAX(1,SUMPRODUCT(($B$2:$B$151=TRUE())*ISNUMBER(Fundamentals!$J$2:$J$151)))))) -> 50 | E7: =AVERAGE(IF(NOT(ISNUMBER(Fundamentals!H7)),50,100*(SUMPRODUCT(($B$2:$B$151=TRUE())*ISNUMBER(Fundamentals!$H$2:$H$151)*(Fundamentals!$H$2:$H$151<Fundamentals!H7))/MAX(1,SUMPRODUCT(($B$2:$B$151=TRUE())*ISNUMBER(Fundamentals!$H$2:$H$151))))),IF(NOT(ISNUMBER(Fundamentals!I7)),50,100*(SUMPRODUCT(($B$2:$B$151=TRUE())*ISNUMBER(Fundamentals!$I$2:$I$151)*(Fundamentals!$I$2:$I$151<Fundamentals!I7))/MAX(1,SUMPRODUCT(($B$2:$B$151=TRUE())*ISNUMBER(Fundamentals!$I$2:$I$151)))))) -> 50 | F7: =IF(Tickers!C7="Financial Services",50,IF(NOT(ISNUMBER(Fundamentals!G7)),50,100*(1-(SUMPRODUCT(($B$2:$B$151=TRUE())*ISNUMBER(Fundamentals!$G$2:$G$151)*(Fundamentals!$G$2:$G$151<Fundamentals!G7))/MAX(1,SUMPRODUCT(($B$2:$B$151=TRUE())*ISNUMBER(Fundamentals!$G$2:$G$151))))))) -> 50 | G7: =AVERAGE(C7:F7) -> 50 | H7: =MIN(100,MAX(0,IF(NOT(ISNUMBER(PriceMetrics!K7)),50,100*(SUMPRODUCT(($B$2:$B$151=TRUE())*ISNUMBER(PriceMetrics!$K$2:$K$151)*(PriceMetrics!$K$2:$K$151<PriceMetrics!K7))/MAX(1,SUMPRODUCT(($B$2:$B$151=TRUE())*ISNUMBER(PriceMetrics!$K$2:$K$151)))))+IF(ISNUMBER(PriceMetrics!L7),10*PriceMetrics!L7,0))) -> 50 | I7: =0.6*IF(NOT(ISNUMBER(PriceMetrics!P7)),50,100*(SUMPRODUCT(($B$2:$B$151=TRUE())*ISNUMBER(PriceMetrics!$P$2:$P$151)*(PriceMetrics!$P$2:$P$151<PriceMetrics!P7))/MAX(1,SUMPRODUCT(($B$2:$B$151=TRUE())*ISNUMBER(PriceMetrics!$P$2:$P$151)))))+0.4*IF(NOT(ISNUMBER(PriceMetrics!H7)),50,IF(PriceMetrics!H7>70,40,IF(PriceMetrics!H7>=50,100,IF(PriceMetrics!H7>=35,60,30)))) -> 50 | J7: =AVERAGE(IF(NOT(ISNUMBER(PriceMetrics!F7)),50,100*(1-(SUMPRODUCT(($B$2:$B$151=TRUE())*ISNUMBER(PriceMetrics!$F$2:$F$151)*(PriceMetrics!$F$2:$F$151<PriceMetrics!F7))/MAX(1,SUMPRODUCT(($B$2:$B$151=TRUE())*ISNUMBER(PriceMetrics!$F$2:$F$151)))))),IF(NOT(ISNUMBER(PriceMetrics!G7)),50,100*(1-(SUMPRODUCT(($B$2:$B$151=TRUE())*ISNUMBER(PriceMetrics!$G$2:$G$151)*(ABS(PriceMetrics!$G$2:$G$151)<ABS(PriceMetrics!G7)))/MAX(1,SUMPRODUCT(($B$2:$B$151=TRUE())*ISNUMBER(PriceMetrics!$G$2:$G$151))))))) -> 50 | K7: =AVERAGE(H7:J7) -> 50 | L7: =Macro!$B$26 -> 53.5 | M7: =Control!$B$3*100*G7/100+Control!$B$4*K7+Control!$B$5*L7 -> 50.7 | N7: =M7+ROW()/1000000 -> 50.700007 | O7: =M7-IF(AND(Tickers!D7="SMALLCAP100",Macro!$B$26<40),Control!$B$11,0) -> 50.7 | P7: =IF(B7=FALSE(),"-",IF(O7>=Control!$B$7,"BUY",IF(O7>=Control!$B$8,"ACCUMULATE",IF(O7>=Control!$B$9,"HOLD","AVOID")))) -> HOLD | Q7: =IF(B7=FALSE(),"",IF(OR(O7>=72,O7<=32),"High",IF(OR(O7>=62,O7<=42),"Medium","Low"))) -> Low | R7: =IF(P7="BUY",Control!$B$12,IF(P7="ACCUMULATE",Control!$B$13,0)) -> 0 | S7: =IF(B7=FALSE(),"",IF(T7=C7,"Rich valuation",IF(T7=E7,"Weak growth",IF(T7=F7,"Balance-sheet leverage",IF(T7=I7,"Negative momentum","High volatility/drawdown"))))) -> Rich valuation | T7: =MIN(C7,E7,F7,I7,J7) -> 50 | U7: =IF(B7=TRUE(),N7,-1000+ROW()/1000000) -> 50.700007
A8: =Tickers!A8 -> BHARATFORG | B8: =Tickers!F8 -> TRUE | C8: =AVERAGE(IF(NOT(ISNUMBER(Fundamentals!C8)),50,IF(Fundamentals!C8<=0,15,100*(1-(SUMPRODUCT(($B$2:$B$151=TRUE())*ISNUMBER(Fundamentals!$C$2:$C$151)*(Fundamentals!$C$2:$C$151>0)*(Fundamentals!$C$2:$C$151<Fundamentals!C8))/MAX(1,SUMPRODUCT(($B$2:$B$151=TRUE())*ISNUMBER(Fundamentals!$C$2:$C$151)*(Fundamentals!$C$2:$C$151>0))))))),IF(NOT(ISNUMBER(Fundamentals!E8)),50,IF(Fundamentals!E8<=0,15,100*(1-(SUMPRODUCT(($B$2:$B$151=TRUE())*ISNUMBER(Fundamentals!$E$2:$E$151)*(Fundamentals!$E$2:$E$151>0)*(Fundamentals!$E$2:$E$151<Fundamentals!E8))/MAX(1,SUMPRODUCT(($B$2:$B$151=TRUE())*ISNUMBER(Fundamentals!$E$2:$E$151)*(Fundamentals!$E$2:$E$151>0)))))))) -> 50 | D8: =AVERAGE(IF(NOT(ISNUMBER(Fundamentals!F8)),50,100*(SUMPRODUCT(($B$2:$B$151=TRUE())*ISNUMBER(Fundamentals!$F$2:$F$151)*(Fundamentals!$F$2:$F$151<Fundamentals!F8))/MAX(1,SUMPRODUCT(($B$2:$B$151=TRUE())*ISNUMBER(Fundamentals!$F$2:$F$151))))),IF(NOT(ISNUMBER(Fundamentals!J8)),50,100*(SUMPRODUCT(($B$2:$B$151=TRUE())*ISNUMBER(Fundamentals!$J$2:$J$151)*(Fundamentals!$J$2:$J$151<Fundamentals!J8))/MAX(1,SUMPRODUCT(($B$2:$B$151=TRUE())*ISNUMBER(Fundamentals!$J$2:$J$151)))))) -> 50 | E8: =AVERAGE(IF(NOT(ISNUMBER(Fundamentals!H8)),50,100*(SUMPRODUCT(($B$2:$B$151=TRUE())*ISNUMBER(Fundamentals!$H$2:$H$151)*(Fundamentals!$H$2:$H$151<Fundamentals!H8))/MAX(1,SUMPRODUCT(($B$2:$B$151=TRUE())*ISNUMBER(Fundamentals!$H$2:$H$151))))),IF(NOT(ISNUMBER(Fundamentals!I8)),50,100*(SUMPRODUCT(($B$2:$B$151=TRUE())*ISNUMBER(Fundamentals!$I$2:$I$151)*(Fundamentals!$I$2:$I$151<Fundamentals!I8))/MAX(1,SUMPRODUCT(($B$2:$B$151=TRUE())*ISNUMBER(Fundamentals!$I$2:$I$151)))))) -> 50 | F8: =IF(Tickers!C8="Financial Services",50,IF(NOT(ISNUMBER(Fundamentals!G8)),50,100*(1-(SUMPRODUCT(($B$2:$B$151=TRUE())*ISNUMBER(Fundamentals!$G$2:$G$151)*(Fundamentals!$G$2:$G$151<Fundamentals!G8))/MAX(1,SUMPRODUCT(($B$2:$B$151=TRUE())*ISNUMBER(Fundamentals!$G$2:$G$151))))))) -> 50 | G8: =AVERAGE(C8:F8) -> 50 | H8: =MIN(100,MAX(0,IF(NOT(ISNUMBER(PriceMetrics!K8)),50,100*(SUMPRODUCT(($B$2:$B$151=TRUE())*ISNUMBER(PriceMetrics!$K$2:$K$151)*(PriceMetrics!$K$2:$K$151<PriceMetrics!K8))/MAX(1,SUMPRODUCT(($B$2:$B$151=TRUE())*ISNUMBER(PriceMetrics!$K$2:$K$151)))))+IF(ISNUMBER(PriceMetrics!L8),10*PriceMetrics!L8,0))) -> 50 | I8: =0.6*IF(NOT(ISNUMBER(PriceMetrics!P8)),50,100*(SUMPRODUCT(($B$2:$B$151=TRUE())*ISNUMBER(PriceMetrics!$P$2:$P$151)*(PriceMetrics!$P$2:$P$151<PriceMetrics!P8))/MAX(1,SUMPRODUCT(($B$2:$B$151=TRUE())*ISNUMBER(PriceMetrics!$P$2:$P$151)))))+0.4*IF(NOT(ISNUMBER(PriceMetrics!H8)),50,IF(PriceMetrics!H8>70,40,IF(PriceMetrics!H8>=50,100,IF(PriceMetrics!H8>=35,60,30)))) -> 50 | J8: =AVERAGE(IF(NOT(ISNUMBER(PriceMetrics!F8)),50,100*(1-(SUMPRODUCT(($B$2:$B$151=TRUE())*ISNUMBER(PriceMetrics!$F$2:$F$151)*(PriceMetrics!$F$2:$F$151<PriceMetrics!F8))/MAX(1,SUMPRODUCT(($B$2:$B$151=TRUE())*ISNUMBER(PriceMetrics!$F$2:$F$151)))))),IF(NOT(ISNUMBER(PriceMetrics!G8)),50,100*(1-(SUMPRODUCT(($B$2:$B$151=TRUE())*ISNUMBER(PriceMetrics!$G$2:$G$151)*(ABS(PriceMetrics!$G$2:$G$151)<ABS(PriceMetrics!G8)))/MAX(1,SUMPRODUCT(($B$2:$B$151=TRUE())*ISNUMBER(PriceMetrics!$G$2:$G$151))))))) -> 50 | K8: =AVERAGE(H8:J8) -> 50 | L8: =Macro!$B$26 -> 53.5 | M8: =Control!$B$3*100*G8/100+Control!$B$4*K8+Control!$B$5*L8 -> 50.7 | N8: =M8+ROW()/1000000 -> 50.700008 | O8: =M8-IF(AND(Tickers!D8="SMALLCAP100",Macro!$B$26<40),Control!$B$11,0) -> 50.7 | P8: =IF(B8=FALSE(),"-",IF(O8>=Control!$B$7,"BUY",IF(O8>=Control!$B$8,"ACCUMULATE",IF(O8>=Control!$B$9,"HOLD","AVOID")))) -> HOLD | Q8: =IF(B8=FALSE(),"",IF(OR(O8>=72,O8<=32),"High",IF(OR(O8>=62,O8<=42),"Medium","Low"))) -> Low | R8: =IF(P8="BUY",Control!$B$12,IF(P8="ACCUMULATE",Control!$B$13,0)) -> 0 | S8: =IF(B8=FALSE(),"",IF(T8=C8,"Rich valuation",IF(T8=E8,"Weak growth",IF(T8=F8,"Balance-sheet leverage",IF(T8=I8,"Negative momentum","High volatility/drawdown"))))) -> Rich valuation | T8: =MIN(C8,E8,F8,I8,J8) -> 50 | U8: =IF(B8=TRUE(),N8,-1000+ROW()/1000000) -> 50.700008
A9: =Tickers!A9 -> BHEL | B9: =Tickers!F9 -> TRUE | C9: =AVERAGE(IF(NOT(ISNUMBER(Fundamentals!C9)),50,IF(Fundamentals!C9<=0,15,100*(1-(SUMPRODUCT(($B$2:$B$151=TRUE())*ISNUMBER(Fundamentals!$C$2:$C$151)*(Fundamentals!$C$2:$C$151>0)*(Fundamentals!$C$2:$C$151<Fundamentals!C9))/MAX(1,SUMPRODUCT(($B$2:$B$151=TRUE())*ISNUMBER(Fundamentals!$C$2:$C$151)*(Fundamentals!$C$2:$C$151>0))))))),IF(NOT(ISNUMBER(Fundamentals!E9)),50,IF(Fundamentals!E9<=0,15,100*(1-(SUMPRODUCT(($B$2:$B$151=TRUE())*ISNUMBER(Fundamentals!$E$2:$E$151)*(Fundamentals!$E$2:$E$151>0)*(Fundamentals!$E$2:$E$151<Fundamentals!E9))/MAX(1,SUMPRODUCT(($B$2:$B$151=TRUE())*ISNUMBER(Fundamentals!$E$2:$E$151)*(Fundamentals!$E$2:$E$151>0)))))))) -> 50 | D9: =AVERAGE(IF(NOT(ISNUMBER(Fundamentals!F9)),50,100*(SUMPRODUCT(($B$2:$B$151=TRUE())*ISNUMBER(Fundamentals!$F$2:$F$151)*(Fundamentals!$F$2:$F$151<Fundamentals!F9))/MAX(1,SUMPRODUCT(($B$2:$B$151=TRUE())*ISNUMBER(Fundamentals!$F$2:$F$151))))),IF(NOT(ISNUMBER(Fundamentals!J9)),50,100*(SUMPRODUCT(($B$2:$B$151=TRUE())*ISNUMBER(Fundamentals!$J$2:$J$151)*(Fundamentals!$J$2:$J$151<Fundamentals!J9))/MAX(1,SUMPRODUCT(($B$2:$B$151=TRUE())*ISNUMBER(Fundamentals!$J$2:$J$151)))))) -> 50 | E9: =AVERAGE(IF(NOT(ISNUMBER(Fundamentals!H9)),50,100*(SUMPRODUCT(($B$2:$B$151=TRUE())*ISNUMBER(Fundamentals!$H$2:$H$151)*(Fundamentals!$H$2:$H$151<Fundamentals!H9))/MAX(1,SUMPRODUCT(($B$2:$B$151=TRUE())*ISNUMBER(Fundamentals!$H$2:$H$151))))),IF(NOT(ISNUMBER(Fundamentals!I9)),50,100*(SUMPRODUCT(($B$2:$B$151=TRUE())*ISNUMBER(Fundamentals!$I$2:$I$151)*(Fundamentals!$I$2:$I$151<Fundamentals!I9))/MAX(1,SUMPRODUCT(($B$2:$B$151=TRUE())*ISNUMBER(Fundamentals!$I$2:$I$151)))))) -> 50 | F9: =IF(Tickers!C9="Financial Services",50,IF(NOT(ISNUMBER(Fundamentals!G9)),50,100*(1-(SUMPRODUCT(($B$2:$B$151=TRUE())*ISNUMBER(Fundamentals!$G$2:$G$151)*(Fundamentals!$G$2:$G$151<Fundamentals!G9))/MAX(1,SUMPRODUCT(($B$2:$B$151=TRUE())*ISNUMBER(Fundamentals!$G$2:$G$151))))))) -> 50 | G9: =AVERAGE(C9:F9) -> 50 | H9: =MIN(100,MAX(0,IF(NOT(ISNUMBER(PriceMetrics!K9)),50,100*(SUMPRODUCT(($B$2:$B$151=TRUE())*ISNUMBER(PriceMetrics!$K$2:$K$151)*(PriceMetrics!$K$2:$K$151<PriceMetrics!K9))/MAX(1,SUMPRODUCT(($B$2:$B$151=TRUE())*ISNUMBER(PriceMetrics!$K$2:$K$151)))))+IF(ISNUMBER(PriceMetrics!L9),10*PriceMetrics!L9,0))) -> 50 | I9: =0.6*IF(NOT(ISNUMBER(PriceMetrics!P9)),50,100*(SUMPRODUCT(($B$2:$B$151=TRUE())*ISNUMBER(PriceMetrics!$P$2:$P$151)*(PriceMetrics!$P$2:$P$151<PriceMetrics!P9))/MAX(1,SUMPRODUCT(($B$2:$B$151=TRUE())*ISNUMBER(PriceMetrics!$P$2:$P$151)))))+0.4*IF(NOT(ISNUMBER(PriceMetrics!H9)),50,IF(PriceMetrics!H9>70,40,IF(PriceMetrics!H9>=50,100,IF(PriceMetrics!H9>=35,60,30)))) -> 50 | J9: =AVERAGE(IF(NOT(ISNUMBER(PriceMetrics!F9)),50,100*(1-(SUMPRODUCT(($B$2:$B$151=TRUE())*ISNUMBER(PriceMetrics!$F$2:$F$151)*(PriceMetrics!$F$2:$F$151<PriceMetrics!F9))/MAX(1,SUMPRODUCT(($B$2:$B$151=TRUE())*ISNUMBER(PriceMetrics!$F$2:$F$151)))))),IF(NOT(ISNUMBER(PriceMetrics!G9)),50,100*(1-(SUMPRODUCT(($B$2:$B$151=TRUE())*ISNUMBER(PriceMetrics!$G$2:$G$151)*(ABS(PriceMetrics!$G$2:$G$151)<ABS(PriceMetrics!G9)))/MAX(1,SUMPRODUCT(($B$2:$B$151=TRUE())*ISNUMBER(PriceMetrics!$G$2:$G$151))))))) -> 50 | K9: =AVERAGE(H9:J9) -> 50 | L9: =Macro!$B$26 -> 53.5 | M9: =Control!$B$3*100*G9/100+Control!$B$4*K9+Control!$B$5*L9 -> 50.7 | N9: =M9+ROW()/1000000 -> 50.700009 | O9: =M9-IF(AND(Tickers!D9="SMALLCAP100",Macro!$B$26<40),Control!$B$11,0) -> 50.7 | P9: =IF(B9=FALSE(),"-",IF(O9>=Control!$B$7,"BUY",IF(O9>=Control!$B$8,"ACCUMULATE",IF(O9>=Control!$B$9,"HOLD","AVOID")))) -> HOLD | Q9: =IF(B9=FALSE(),"",IF(OR(O9>=72,O9<=32),"High",IF(OR(O9>=62,O9<=42),"Medium","Low"))) -> Low | R9: =IF(P9="BUY",Control!$B$12,IF(P9="ACCUMULATE",Control!$B$13,0)) -> 0 | S9: =IF(B9=FALSE(),"",IF(T9=C9,"Rich valuation",IF(T9=E9,"Weak growth",IF(T9=F9,"Balance-sheet leverage",IF(T9=I9,"Negative momentum","High volatility/drawdown"))))) -> Rich valuation | T9: =MIN(C9,E9,F9,I9,J9) -> 50 | U9: =IF(B9=TRUE(),N9,-1000+ROW()/1000000) -> 50.700009
A10: =Tickers!A10 -> COFORGE | B10: =Tickers!F10 -> TRUE | C10: =AVERAGE(IF(NOT(ISNUMBER(Fundamentals!C10)),50,IF(Fundamentals!C10<=0,15,100*(1-(SUMPRODUCT(($B$2:$B$151=TRUE())*ISNUMBER(Fundamentals!$C$2:$C$151)*(Fundamentals!$C$2:$C$151>0)*(Fundamentals!$C$2:$C$151<Fundamentals!C10))/MAX(1,SUMPRODUCT(($B$2:$B$151=TRUE())*ISNUMBER(Fundamentals!$C$2:$C$151)*(Fundamentals!$C$2:$C$151>0))))))),IF(NOT(ISNUMBER(Fundamentals!E10)),50,IF(Fundamentals!E10<=0,15,100*(1-(SUMPRODUCT(($B$2:$B$151=TRUE())*ISNUMBER(Fundamentals!$E$2:$E$151)*(Fundamentals!$E$2:$E$151>0)*(Fundamentals!$E$2:$E$151<Fundamentals!E10))/MAX(1,SUMPRODUCT(($B$2:$B$151=TRUE())*ISNUMBER(Fundamentals!$E$2:$E$151)*(Fundamentals!$E$2:$E$151>0)))))))) -> 50 | D10: =AVERAGE(IF(NOT(ISNUMBER(Fundamentals!F10)),50,100*(SUMPRODUCT(($B$2:$B$151=TRUE())*ISNUMBER(Fundamentals!$F$2:$F$151)*(Fundamentals!$F$2:$F$151<Fundamentals!F10))/MAX(1,SUMPRODUCT(($B$2:$B$151=TRUE())*ISNUMBER(Fundamentals!$F$2:$F$151))))),IF(NOT(ISNUMBER(Fundamentals!J10)),50,100*(SUMPRODUCT(($B$2:$B$151=TRUE())*ISNUMBER(Fundamentals!$J$2:$J$151)*(Fundamentals!$J$2:$J$151<Fundamentals!J10))/MAX(1,SUMPRODUCT(($B$2:$B$151=TRUE())*ISNUMBER(Fundamentals!$J$2:$J$151)))))) -> 50 | E10: =AVERAGE(IF(NOT(ISNUMBER(Fundamentals!H10)),50,100*(SUMPRODUCT(($B$2:$B$151=TRUE())*ISNUMBER(Fundamentals!$H$2:$H$151)*(Fundamentals!$H$2:$H$151<Fundamentals!H10))/MAX(1,SUMPRODUCT(($B$2:$B$151=TRUE())*ISNUMBER(Fundamentals!$H$2:$H$151))))),IF(NOT(ISNUMBER(Fundamentals!I10)),50,100*(SUMPRODUCT(($B$2:$B$151=TRUE())*ISNUMBER(Fundamentals!$I$2:$I$151)*(Fundamentals!$I$2:$I$151<Fundamentals!I10))/MAX(1,SUMPRODUCT(($B$2:$B$151=TRUE())*ISNUMBER(Fundamentals!$I$2:$I$151)))))) -> 50 | F10: =IF(Tickers!C10="Financial Services",50,IF(NOT(ISNUMBER(Fundamentals!G10)),50,100*(1-(SUMPRODUCT(($B$2:$B$151=TRUE())*ISNUMBER(Fundamentals!$G$2:$G$151)*(Fundamentals!$G$2:$G$151<Fundamentals!G10))/MAX(1,SUMPRODUCT(($B$2:$B$151=TRUE())*ISNUMBER(Fundamentals!$G$2:$G$151))))))) -> 50 | G10: =AVERAGE(C10:F10) -> 50 | H10: =MIN(100,MAX(0,IF(NOT(ISNUMBER(PriceMetrics!K10)),50,100*(SUMPRODUCT(($B$2:$B$151=TRUE())*ISNUMBER(PriceMetrics!$K$2:$K$151)*(PriceMetrics!$K$2:$K$151<PriceMetrics!K10))/MAX(1,SUMPRODUCT(($B$2:$B$151=TRUE())*ISNUMBER(PriceMetrics!$K$2:$K$151)))))+IF(ISNUMBER(PriceMetrics!L10),10*PriceMetrics!L10,0))) -> 50 | I10: =0.6*IF(NOT(ISNUMBER(PriceMetrics!P10)),50,100*(SUMPRODUCT(($B$2:$B$151=TRUE())*ISNUMBER(PriceMetrics!$P$2:$P$151)*(PriceMetrics!$P$2:$P$151<PriceMetrics!P10))/MAX(1,SUMPRODUCT(($B$2:$B$151=TRUE())*ISNUMBER(PriceMetrics!$P$2:$P$151)))))+0.4*IF(NOT(ISNUMBER(PriceMetrics!H10)),50,IF(PriceMetrics!H10>70,40,IF(PriceMetrics!H10>=50,100,IF(PriceMetrics!H10>=35,60,30)))) -> 50 | J10: =AVERAGE(IF(NOT(ISNUMBER(PriceMetrics!F10)),50,100*(1-(SUMPRODUCT(($B$2:$B$151=TRUE())*ISNUMBER(PriceMetrics!$F$2:$F$151)*(PriceMetrics!$F$2:$F$151<PriceMetrics!F10))/MAX(1,SUMPRODUCT(($B$2:$B$151=TRUE())*ISNUMBER(PriceMetrics!$F$2:$F$151)))))),IF(NOT(ISNUMBER(PriceMetrics!G10)),50,100*(1-(SUMPRODUCT(($B$2:$B$151=TRUE())*ISNUMBER(PriceMetrics!$G$2:$G$151)*(ABS(PriceMetrics!$G$2:$G$151)<ABS(PriceMetrics!G10)))/MAX(1,SUMPRODUCT(($B$2:$B$151=TRUE())*ISNUMBER(PriceMetrics!$G$2:$G$151))))))) -> 50 | K10: =AVERAGE(H10:J10) -> 50 | L10: =Macro!$B$26 -> 53.5 | M10: =Control!$B$3*100*G10/100+Control!$B$4*K10+Control!$B$5*L10 -> 50.7 | N10: =M10+ROW()/1000000 -> 50.70001 | O10: =M10-IF(AND(Tickers!D10="SMALLCAP100",Macro!$B$26<40),Control!$B$11,0) -> 50.7 | P10: =IF(B10=FALSE(),"-",IF(O10>=Control!$B$7,"BUY",IF(O10>=Control!$B$8,"ACCUMULATE",IF(O10>=Control!$B$9,"HOLD","AVOID")))) -> HOLD | Q10: =IF(B10=FALSE(),"",IF(OR(O10>=72,O10<=32),"High",IF(OR(O10>=62,O10<=42),"Medium","Low"))) -> Low | R10: =IF(P10="BUY",Control!$B$12,IF(P10="ACCUMULATE",Control!$B$13,0)) -> 0 | S10: =IF(B10=FALSE(),"",IF(T10=C10,"Rich valuation",IF(T10=E10,"Weak growth",IF(T10=F10,"Balance-sheet leverage",IF(T10=I10,"Negative momentum","High volatility/drawdown"))))) -> Rich valuation | T10: =MIN(C10,E10,F10,I10,J10) -> 50 | U10: =IF(B10=TRUE(),N10,-1000+ROW()/1000000) -> 50.70001
A11: =Tickers!A11 -> COLPAL | B11: =Tickers!F11 -> TRUE | C11: =AVERAGE(IF(NOT(ISNUMBER(Fundamentals!C11)),50,IF(Fundamentals!C11<=0,15,100*(1-(SUMPRODUCT(($B$2:$B$151=TRUE())*ISNUMBER(Fundamentals!$C$2:$C$151)*(Fundamentals!$C$2:$C$151>0)*(Fundamentals!$C$2:$C$151<Fundamentals!C11))/MAX(1,SUMPRODUCT(($B$2:$B$151=TRUE())*ISNUMBER(Fundamentals!$C$2:$C$151)*(Fundamentals!$C$2:$C$151>0))))))),IF(NOT(ISNUMBER(Fundamentals!E11)),50,IF(Fundamentals!E11<=0,15,100*(1-(SUMPRODUCT(($B$2:$B$151=TRUE())*ISNUMBER(Fundamentals!$E$2:$E$151)*(Fundamentals!$E$2:$E$151>0)*(Fundamentals!$E$2:$E$151<Fundamentals!E11))/MAX(1,SUMPRODUCT(($B$2:$B$151=TRUE())*ISNUMBER(Fundamentals!$E$2:$E$151)*(Fundamentals!$E$2:$E$151>0)))))))) -> 50 | D11: =AVERAGE(IF(NOT(ISNUMBER(Fundamentals!F11)),50,100*(SUMPRODUCT(($B$2:$B$151=TRUE())*ISNUMBER(Fundamentals!$F$2:$F$151)*(Fundamentals!$F$2:$F$151<Fundamentals!F11))/MAX(1,SUMPRODUCT(($B$2:$B$151=TRUE())*ISNUMBER(Fundamentals!$F$2:$F$151))))),IF(NOT(ISNUMBER(Fundamentals!J11)),50,100*(SUMPRODUCT(($B$2:$B$151=TRUE())*ISNUMBER(Fundamentals!$J$2:$J$151)*(Fundamentals!$J$2:$J$151<Fundamentals!J11))/MAX(1,SUMPRODUCT(($B$2:$B$151=TRUE())*ISNUMBER(Fundamentals!$J$2:$J$151)))))) -> 50 | E11: =AVERAGE(IF(NOT(ISNUMBER(Fundamentals!H11)),50,100*(SUMPRODUCT(($B$2:$B$151=TRUE())*ISNUMBER(Fundamentals!$H$2:$H$151)*(Fundamentals!$H$2:$H$151<Fundamentals!H11))/MAX(1,SUMPRODUCT(($B$2:$B$151=TRUE())*ISNUMBER(Fundamentals!$H$2:$H$151))))),IF(NOT(ISNUMBER(Fundamentals!I11)),50,100*(SUMPRODUCT(($B$2:$B$151=TRUE())*ISNUMBER(Fundamentals!$I$2:$I$151)*(Fundamentals!$I$2:$I$151<Fundamentals!I11))/MAX(1,SUMPRODUCT(($B$2:$B$151=TRUE())*ISNUMBER(Fundamentals!$I$2:$I$151)))))) -> 50 | F11: =IF(Tickers!C11="Financial Services",50,IF(NOT(ISNUMBER(Fundamentals!G11)),50,100*(1-(SUMPRODUCT(($B$2:$B$151=TRUE())*ISNUMBER(Fundamentals!$G$2:$G$151)*(Fundamentals!$G$2:$G$151<Fundamentals!G11))/MAX(1,SUMPRODUCT(($B$2:$B$151=TRUE())*ISNUMBER(Fundamentals!$G$2:$G$151))))))) -> 50 | G11: =AVERAGE(C11:F11) -> 50 | H11: =MIN(100,MAX(0,IF(NOT(ISNUMBER(PriceMetrics!K11)),50,100*(SUMPRODUCT(($B$2:$B$151=TRUE())*ISNUMBER(PriceMetrics!$K$2:$K$151)*(PriceMetrics!$K$2:$K$151<PriceMetrics!K11))/MAX(1,SUMPRODUCT(($B$2:$B$151=TRUE())*ISNUMBER(PriceMetrics!$K$2:$K$151)))))+IF(ISNUMBER(PriceMetrics!L11),10*PriceMetrics!L11,0))) -> 50 | I11: =0.6*IF(NOT(ISNUMBER(PriceMetrics!P11)),50,100*(SUMPRODUCT(($B$2:$B$151=TRUE())*ISNUMBER(PriceMetrics!$P$2:$P$151)*(PriceMetrics!$P$2:$P$151<PriceMetrics!P11))/MAX(1,SUMPRODUCT(($B$2:$B$151=TRUE())*ISNUMBER(PriceMetrics!$P$2:$P$151)))))+0.4*IF(NOT(ISNUMBER(PriceMetrics!H11)),50,IF(PriceMetrics!H11>70,40,IF(PriceMetrics!H11>=50,100,IF(PriceMetrics!H11>=35,60,30)))) -> 50 | J11: =AVERAGE(IF(NOT(ISNUMBER(PriceMetrics!F11)),50,100*(1-(SUMPRODUCT(($B$2:$B$151=TRUE())*ISNUMBER(PriceMetrics!$F$2:$F$151)*(PriceMetrics!$F$2:$F$151<PriceMetrics!F11))/MAX(1,SUMPRODUCT(($B$2:$B$151=TRUE())*ISNUMBER(PriceMetrics!$F$2:$F$151)))))),IF(NOT(ISNUMBER(PriceMetrics!G11)),50,100*(1-(SUMPRODUCT(($B$2:$B$151=TRUE())*ISNUMBER(PriceMetrics!$G$2:$G$151)*(ABS(PriceMetrics!$G$2:$G$151)<ABS(PriceMetrics!G11)))/MAX(1,SUMPRODUCT(($B$2:$B$151=TRUE())*ISNUMBER(PriceMetrics!$G$2:$G$151))))))) -> 50 | K11: =AVERAGE(H11:J11) -> 50 | L11: =Macro!$B$26 -> 53.5 | M11: =Control!$B$3*100*G11/100+Control!$B$4*K11+Control!$B$5*L11 -> 50.7 | N11: =M11+ROW()/1000000 -> 50.700011 | O11: =M11-IF(AND(Tickers!D11="SMALLCAP100",Macro!$B$26<40),Control!$B$11,0) -> 50.7 | P11: =IF(B11=FALSE(),"-",IF(O11>=Control!$B$7,"BUY",IF(O11>=Control!$B$8,"ACCUMULATE",IF(O11>=Control!$B$9,"HOLD","AVOID")))) -> HOLD | Q11: =IF(B11=FALSE(),"",IF(OR(O11>=72,O11<=32),"High",IF(OR(O11>=62,O11<=42),"Medium","Low"))) -> Low | R11: =IF(P11="BUY",Control!$B$12,IF(P11="ACCUMULATE",Control!$B$13,0)) -> 0 | S11: =IF(B11=FALSE(),"",IF(T11=C11,"Rich valuation",IF(T11=E11,"Weak growth",IF(T11=F11,"Balance-sheet leverage",IF(T11=I11,"Negative momentum","High volatility/drawdown"))))) -> Rich valuation | T11: =MIN(C11,E11,F11,I11,J11) -> 50 | U11: =IF(B11=TRUE(),N11,-1000+ROW()/1000000) -> 50.700011
A12: =Tickers!A12 -> DABUR | B12: =Tickers!F12 -> TRUE | C12: =AVERAGE(IF(NOT(ISNUMBER(Fundamentals!C12)),50,IF(Fundamentals!C12<=0,15,100*(1-(SUMPRODUCT(($B$2:$B$151=TRUE())*ISNUMBER(Fundamentals!$C$2:$C$151)*(Fundamentals!$C$2:$C$151>0)*(Fundamentals!$C$2:$C$151<Fundamentals!C12))/MAX(1,SUMPRODUCT(($B$2:$B$151=TRUE())*ISNUMBER(Fundamentals!$C$2:$C$151)*(Fundamentals!$C$2:$C$151>0))))))),IF(NOT(ISNUMBER(Fundamentals!E12)),50,IF(Fundamentals!E12<=0,15,100*(1-(SUMPRODUCT(($B$2:$B$151=TRUE())*ISNUMBER(Fundamentals!$E$2:$E$151)*(Fundamentals!$E$2:$E$151>0)*(Fundamentals!$E$2:$E$151<Fundamentals!E12))/MAX(1,SUMPRODUCT(($B$2:$B$151=TRUE())*ISNUMBER(Fundamentals!$E$2:$E$151)*(Fundamentals!$E$2:$E$151>0)))))))) -> 50 | D12: =AVERAGE(IF(NOT(ISNUMBER(Fundamentals!F12)),50,100*(SUMPRODUCT(($B$2:$B$151=TRUE())*ISNUMBER(Fundamentals!$F$2:$F$151)*(Fundamentals!$F$2:$F$151<Fundamentals!F12))/MAX(1,SUMPRODUCT(($B$2:$B$151=TRUE())*ISNUMBER(Fundamentals!$F$2:$F$151))))),IF(NOT(ISNUMBER(Fundamentals!J12)),50,100*(SUMPRODUCT(($B$2:$B$151=TRUE())*ISNUMBER(Fundamentals!$J$2:$J$151)*(Fundamentals!$J$2:$J$151<Fundamentals!J12))/MAX(1,SUMPRODUCT(($B$2:$B$151=TRUE())*ISNUMBER(Fundamentals!$J$2:$J$151)))))) -> 50 | E12: =AVERAGE(IF(NOT(ISNUMBER(Fundamentals!H12)),50,100*(SUMPRODUCT(($B$2:$B$151=TRUE())*ISNUMBER(Fundamentals!$H$2:$H$151)*(Fundamentals!$H$2:$H$151<Fundamentals!H12))/MAX(1,SUMPRODUCT(($B$2:$B$151=TRUE())*ISNUMBER(Fundamentals!$H$2:$H$151))))),IF(NOT(ISNUMBER(Fundamentals!I12)),50,100*(SUMPRODUCT(($B$2:$B$151=TRUE())*ISNUMBER(Fundamentals!$I$2:$I$151)*(Fundamentals!$I$2:$I$151<Fundamentals!I12))/MAX(1,SUMPRODUCT(($B$2:$B$151=TRUE())*ISNUMBER(Fundamentals!$I$2:$I$151)))))) -> 50 | F12: =IF(Tickers!C12="Financial Services",50,IF(NOT(ISNUMBER(Fundamentals!G12)),50,100*(1-(SUMPRODUCT(($B$2:$B$151=TRUE())*ISNUMBER(Fundamentals!$G$2:$G$151)*(Fundamentals!$G$2:$G$151<Fundamentals!G12))/MAX(1,SUMPRODUCT(($B$2:$B$151=TRUE())*ISNUMBER(Fundamentals!$G$2:$G$151))))))) -> 50 | G12: =AVERAGE(C12:F12) -> 50 | H12: =MIN(100,MAX(0,IF(NOT(ISNUMBER(PriceMetrics!K12)),50,100*(SUMPRODUCT(($B$2:$B$151=TRUE())*ISNUMBER(PriceMetrics!$K$2:$K$151)*(PriceMetrics!$K$2:$K$151<PriceMetrics!K12))/MAX(1,SUMPRODUCT(($B$2:$B$151=TRUE())*ISNUMBER(PriceMetrics!$K$2:$K$151)))))+IF(ISNUMBER(PriceMetrics!L12),10*PriceMetrics!L12,0))) -> 50 | I12: =0.6*IF(NOT(ISNUMBER(PriceMetrics!P12)),50,100*(SUMPRODUCT(($B$2:$B$151=TRUE())*ISNUMBER(PriceMetrics!$P$2:$P$151)*(PriceMetrics!$P$2:$P$151<PriceMetrics!P12))/MAX(1,SUMPRODUCT(($B$2:$B$151=TRUE())*ISNUMBER(PriceMetrics!$P$2:$P$151)))))+0.4*IF(NOT(ISNUMBER(PriceMetrics!H12)),50,IF(PriceMetrics!H12>70,40,IF(PriceMetrics!H12>=50,100,IF(PriceMetrics!H12>=35,60,30)))) -> 50 | J12: =AVERAGE(IF(NOT(ISNUMBER(PriceMetrics!F12)),50,100*(1-(SUMPRODUCT(($B$2:$B$151=TRUE())*ISNUMBER(PriceMetrics!$F$2:$F$151)*(PriceMetrics!$F$2:$F$151<PriceMetrics!F12))/MAX(1,SUMPRODUCT(($B$2:$B$151=TRUE())*ISNUMBER(PriceMetrics!$F$2:$F$151)))))),IF(NOT(ISNUMBER(PriceMetrics!G12)),50,100*(1-(SUMPRODUCT(($B$2:$B$151=TRUE())*ISNUMBER(PriceMetrics!$G$2:$G$151)*(ABS(PriceMetrics!$G$2:$G$151)<ABS(PriceMetrics!G12)))/MAX(1,SUMPRODUCT(($B$2:$B$151=TRUE())*ISNUMBER(PriceMetrics!$G$2:$G$151))))))) -> 50 | K12: =AVERAGE(H12:J12) -> 50 | L12: =Macro!$B$26 -> 53.5 | M12: =Control!$B$3*100*G12/100+Control!$B$4*K12+Control!$B$5*L12 -> 50.7 | N12: =M12+ROW()/1000000 -> 50.700012 | O12: =M12-IF(AND(Tickers!D12="SMALLCAP100",Macro!$B$26<40),Control!$B$11,0) -> 50.7 | P12: =IF(B12=FALSE(),"-",IF(O12>=Control!$B$7,"BUY",IF(O12>=Control!$B$8,"ACCUMULATE",IF(O12>=Control!$B$9,"HOLD","AVOID")))) -> HOLD | Q12: =IF(B12=FALSE(),"",IF(OR(O12>=72,O12<=32),"High",IF(OR(O12>=62,O12<=42),"Medium","Low"))) -> Low | R12: =IF(P12="BUY",Control!$B$12,IF(P12="ACCUMULATE",Control!$B$13,0)) -> 0 | S12: =IF(B12=FALSE(),"",IF(T12=C12,"Rich valuation",IF(T12=E12,"Weak growth",IF(T12=F12,"Balance-sheet leverage",IF(T12=I12,"Negative momentum","High volatility/drawdown"))))) -> Rich valuation | T12: =MIN(C12,E12,F12,I12,J12) -> 50 | U12: =IF(B12=TRUE(),N12,-1000+ROW()/1000000) -> 50.700012
